<?xml version="1.0" ?>
<robot name="urdf">
  <link name="base_footprint" />

  <joint name="base_footprint_to_base_link" type="fixed">
    <parent link="base_footprint"/>
    <child link="base_link"/>
  </joint>

  <link name="base_link">
    <inertial>
      <origin xyz="-0.00280638761136618 9.22799255059434E-05 -0.00823780680525314" rpy="0 0 0" />
      <mass value="2.73624245548653" />
      <inertia ixx="0.0111853471576075" ixy="-7.2511498712482E-11" ixz="0.000255799746468985" iyy="0.0161314353661535" iyz="1.81571166508761E-07" izz="0.0239017300755925" />
    </inertial>
    <visual>
      <origin xyz="0 0 0" rpy="0 0 0" />
      <geometry>
        <mesh filename="package://final/meshes/base_link.STL" />
      </geometry>
      <material name="">
        <color rgba="0.792156862745098 0.819607843137255 0.933333333333333 1" />
      </material>
    </visual>
    <collision>
      <origin xyz="0 0 0" rpy="0 0 0" />
      <geometry>
        <mesh filename="package://final/meshes/base_link.STL" />
      </geometry>
    </collision>
  </link>

  <link name="Left_forward_wheel">
    <inertial>
      <origin xyz="1.2490009027033E-16 -6.1409211049579E-16 -0.0318963397161268" rpy="0 0 0" />
      <mass value="0.38693434007123" />
      <inertia ixx="0.000164665684225832" ixy="1.03435021381098E-16" ixz="2.79933590586541E-16" iyy="0.000164665684225701" iyz="1.53586588595806E-16" izz="0.000205539151193427" />
    </inertial>
    <visual>
      <origin xyz="0 0 0" rpy="0 0 0" />
      <geometry>
        <mesh filename="package://final/meshes/Left_forward_wheel.STL" />
      </geometry>
      <material name="">
        <color rgba="0.752941176470588 0.752941176470588 0.752941176470588 1" />
      </material>
    </visual>
    <collision>
      <origin xyz="0 0 0" rpy="0 0 0" />
      <geometry>
        <mesh filename="package://final/meshes/Left_forward_wheel.STL" />
      </geometry>
    </collision>
  </link>

  <joint name="Left_forward_joint" type="continuous">
    <origin xyz="0.1135 0.165 -0.0179" rpy="-1.5708 0 0" />
    <parent link="base_link" />
    <child link="Left_forward_wheel" />
    <axis xyz="0 0 1" />
    <dynamics damping="0.1" friction="0.1" />
  </joint>

  <link name="Right_forward_wheel">
    <inertial>
      <origin xyz="-1.2490009027033E-16 4.85722573273506E-17 -0.0318963396900528" rpy="0 0 0" />
      <mass value="0.386934339646562" />
      <inertia ixx="0.00016466568423101" ixy="-3.19541061769317E-17" ixz="-3.82361260302432E-17" iyy="0.000164665684231041" iyz="-2.40756939158418E-17" izz="0.000205539151181393" />
    </inertial>
    <visual>
      <origin xyz="0 0 0" rpy="0 0 0" />
      <geometry>
        <mesh filename="package://final/meshes/Right_forward_wheel.STL" />
      </geometry>
      <material name="">
        <color rgba="0.752941176470588 0.752941176470588 0.752941176470588 1" />
      </material>
    </visual>
    <collision>
      <origin xyz="0 0 0" rpy="0 0 0" />
      <geometry>
        <mesh filename="package://final/meshes/Right_forward_wheel.STL" />
      </geometry>
    </collision>
  </link>

  <joint name="Right_forward_joint" type="continuous">
    <origin xyz="0.1135 -0.165 -0.0179" rpy="1.5708 0 0" />
    <parent link="base_link" />
    <child link="Right_forward_wheel" />
    <axis xyz="0 0 -1" />
    <dynamics damping="0.1" friction="0.1" />
  </joint>

  <link name="Left_backward_wheel">
    <inertial>
      <origin xyz="-3.88578058618805E-16 1.52655665885959E-16 -0.0318963396983103" rpy="0 0 0" />
      <mass value="0.38693433977405" />
      <inertia ixx="0.000164665684224543" ixy="-5.44366971754961E-17" ixz="-1.64638873428518E-17" iyy="0.000164665684224467" iyz="-4.73291942910437E-17" izz="0.000205539151192063" />
    </inertial>
    <visual>
      <origin xyz="0 0 0" rpy="0 0 0" />
      <geometry>
        <mesh filename="package://final/meshes/Left_backward_wheel.STL" />
      </geometry>
      <material name="">
        <color rgba="0.752941176470588 0.752941176470588 0.752941176470588 1" />
      </material>
    </visual>
    <collision>
      <origin xyz="0 0 0" rpy="0 0 0" />
      <geometry>
        <mesh filename="package://final/meshes/Left_backward_wheel.STL" />
      </geometry>
    </collision>
  </link>

  <joint name="Left_backward_joint" type="continuous">
    <origin xyz="-0.1135 0.165 -0.0179" rpy="-1.5708 0 0" />
    <parent link="base_link" />
    <child link="Left_backward_wheel" />
    <axis xyz="0 0 1" />
    <dynamics damping="0.1" friction="0.1" />
  </joint>

  <link name="Right_backward_wheel">
    <inertial>
      <origin xyz="3.88578058618805E-16 3.81639164714898E-17 -0.0318963396918449" rpy="0 0 0" />
      <mass value="0.386934339673269" />
      <inertia ixx="0.000164665684230379" ixy="7.84436153661023E-17" ixz="-5.11751895742631E-17" iyy="0.000164665684230335" iyz="-1.24644074562022E-17" izz="0.000205539151179241" />
    </inertial>
    <visual>
      <origin xyz="0 0 0" rpy="0 0 0" />
      <geometry>
        <mesh filename="package://final/meshes/Right_backward_wheel.STL" />
      </geometry>
      <material name="">
        <color rgba="0.752941176470588 0.752941176470588 0.752941176470588 1" />
      </material>
    </visual>
    <collision>
      <origin xyz="0 0 0" rpy="0 0 0" />
      <geometry>
        <mesh filename="package://final/meshes/Right_backward_wheel.STL" />
      </geometry>
    </collision>
  </link>

  <joint name="Right_backward_joint" type="continuous">
    <origin xyz="-0.1135 -0.165 -0.0179" rpy="1.5708 0 0" />
    <parent link="base_link" />
    <child link="Right_backward_wheel" />
    <axis xyz="0 0 -1" />
    <dynamics damping="0.1" friction="0.1" />
  </joint>

  <link name="lidar">
    <inertial>
      <origin xyz="-0.00829409957033964 -6.93889390390723E-18 0.010701142222791" rpy="0 0 0" />
      <mass value="0.146695752131392" />
      <inertia ixx="6.22721120792818E-05" ixy="-1.8353446398283E-20" ixz="-1.88658076337422E-05" iyy="0.000109673997590948" iyz="-8.39148657969651E-21" izz="0.000125682524275729" />
    </inertial>
    <visual>
      <origin xyz="0 0 0" rpy="0 0 0" />
      <geometry>
        <mesh filename="package://final/meshes/lidar.STL" />
      </geometry>
      <material name="">
        <color rgba="0.792156862745098 0.819607843137255 0.933333333333333 1" />
      </material>
    </visual>
    <collision>
      <origin xyz="0 0 0" rpy="0 0 0" />
      <geometry>
        <mesh filename="package://final/meshes/lidar.STL" />
      </geometry>
    </collision>
  </link>

  <joint name="lidar_joint" type="fixed">
    <origin xyz="0.108 0 0.042" rpy="0 0 0" />
    <parent link="base_link" />
    <child link="lidar" />
    <axis xyz="0 0 0" />
    <dynamics damping="0.1" friction="0.1" />
  </joint>

  <gazebo reference="lidar">
    <sensor name="lidar_sensor" type="ray">
      <pose>0 0 0 0 0 0</pose>
      <visualize>true</visualize>
      <update_rate>10.0</update_rate>
      <ray>
        <scan>
          <horizontal>
            <samples>720</samples>
            <resolution>1</resolution>
            <min_angle>-2.5708</min_angle>
            <max_angle>2.5708</max_angle>
          </horizontal>
        </scan>
        <range>
          <min>0.1</min>
          <max>10.0</max>
          <resolution>0.01</resolution>
        </range>
        <noise>
          <type>gaussian</type>
          <mean>0.0</mean>
          <stddev>0.01</stddev>
        </noise>
      </ray>
      <plugin name="gazebo_ros_laser_controller" filename="libgazebo_ros_laser.so">
        <topicName>scan</topicName>
        <frameName>lidar</frameName>
      </plugin>
    </sensor>
  </gazebo>

  <link name="rear_camera">
    <visual>
      <geometry>
        <box size="0.1 0.05 0.03"/>
      </geometry>
      <material name="Gray">
        <color rgba="0.5 0.5 0.5 0.0"/>
      </material>
    </visual>
    <inertial>
      <mass value="0.1"/>
      <origin xyz="0 0 0"/>
      <inertia ixx="0.01" iyy="0.01" izz="0.01" ixy="0" ixz="0" iyz="0"/>
    </inertial>
  </link>
  <joint name="rear_camera_joint" type="fixed">
    <parent link="base_link"/>
    <child link="rear_camera"/>
    <origin xyz="-0.15 0 0.07" rpy="0 0 3.14"/>
  </joint>

  <gazebo reference="rear_camera">
    <sensor name="camera_rear" type="camera">
      <update_rate>30</update_rate>
      <camera>
        <horizontal_fov>1.396</horizontal_fov>
        <image>
          <width>640</width>
          <height>480</height>
          <format>R8G8B8</format>
        </image>
        <clip>
          <near>0.02</near>
          <far>100</far>
        </clip>
      </camera>
      <plugin name="gazebo_ros_camera" filename="libgazebo_ros_camera.so">
        <alwaysOn>true</alwaysOn>
        <updateRate>30.0</updateRate>
        <cameraName>rear_camera</cameraName>
        <imageTopicName>/rear_camera/image_raw</imageTopicName>
        <cameraInfoTopicName>/rear_camera/camera_info</cameraInfoTopicName>
        <frameName>rear_camera</frameName>
      </plugin>
    </sensor>
  </gazebo>

  <!-- front camera -->

  <link name="front_camera">
    <visual>
      <geometry>
        <box size="0.1 0.05 0.03"/>
      </geometry>
      <material name="Gray">
        <color rgba="0.5 0.5 0.5 0.0"/>
      </material>
    </visual>
    <inertial>
      <mass value="0.1"/>
      <origin xyz="0 0 0"/>
      <inertia ixx="0.01" iyy="0.01" izz="0.01" ixy="0" ixz="0" iyz="0"/>
    </inertial>
  </link>
  <joint name="front_camera_joint" type="fixed">
    <parent link="base_link"/>
    <child link="front_camera"/>
    <origin xyz="0.12 0 0.092" rpy="0 0 0"/>
  </joint>

  <gazebo reference="front_camera">
    <sensor name="front_camera" type="camera">
      <update_rate>30</update_rate>
      <camera>
        <horizontal_fov>1.396</horizontal_fov>
        <image>
          <width>640</width>
          <height>480</height>
          <format>R8G8B8</format>
        </image>
        <clip>
          <near>0.02</near>
          <far>100</far>
        </clip>
      </camera>
      <plugin name="gazebo_ros_camera" filename="libgazebo_ros_camera.so">
        <alwaysOn>true</alwaysOn>
        <updateRate>30.0</updateRate>
        <cameraName>front_camera</cameraName>
        <imageTopicName>/front_camera/image_raw</imageTopicName>
        <cameraInfoTopicName>/front_camera/camera_info</cameraInfoTopicName>
        <frameName>front_camera</frameName>
      </plugin>
    </sensor>
  </gazebo>


  <gazebo>
    <plugin name="omni_steering" filename="libgazebo_ros_planar_move.so">
      <commandTopic>cmd_vel</commandTopic>
      <odometryTopic>odom</odometryTopic>
      <odometryFrame>odom</odometryFrame>
      <odometryRate>20.0</odometryRate>
      <robotBaseFrame>base_footprint</robotBaseFrame>
      <cmdTimeout>1.0</cmdTimeout>
    </plugin>
  </gazebo>
</robot>
